<mujoco>
  <compiler inertiafromgeom="true" angle="degree" coordinate="local" />
  <option timestep="0.02" integrator="RK4" />
  <default>
    <joint limited="false" armature="0" damping="0" />
    <geom condim="3" conaffinity="0" margin="0" friction="1 0.5 0.5" rgba="0.8 0.6 0.4 1" density="100" />
  </default>
  <asset>
    <texture type="skybox" builtin="gradient" width="100" height="100" rgb1="1 1 1" rgb2="0 0 0" />
    <texture name="texgeom" type="cube" builtin="flat" mark="cross" width="127" height="1278" rgb1="0.8 0.6 0.4" rgb2="0.8 0.6 0.4" markrgb="1 1 1" random="0.01" />
    <texture name="texplane" type="2d" builtin="checker" rgb1="0 0 0" rgb2="0.8 0.8 0.8" width="100" height="100" />
    <material name='MatPlane' texture="texplane" shininess="1" texrepeat="30 30" specular="1"  reflectance="0.5" />
    <material name='geom' texture="texgeom" texuniform="true" />
  </asset>
  <worldbody>
    <light directional="true" cutoff="100" exponent="1" diffuse="1 1 1" specular=".1 .1 .1" pos="0 0 1.3" dir="-0 0 -1.3" />
    <geom name='floor' pos='0 0 0' size='40 40 40' type='plane' conaffinity='1' rgba='0.8 0.9 0.8 1' condim='3' />
    <body name="torso" pos="0 0 0.0">
            <geom name="ball_geom" friction= "2.0" conaffinity="1" contype="1" density="1000" type="sphere" size="0.5" pos="0 0 0.5"/>
            <joint axis="1 0 0" name="x-rotor" pos="0 0 0.2" type="slide"/>
            <joint axis="0 1 0" name="y-rotor" pos="0 0 0.2" type="slide"/>
            <joint axis="0 0 1" limited="false" name="rot" pos="0 0 0" type="hinge"/>
    </body>
  </worldbody>
  <actuator>
        <motor ctrllimited="true" ctrlrange="-1 1" gear="100.0" joint="x-rotor"/>
        <motor ctrllimited="true" ctrlrange="-1 1" gear="100.0" joint="y-rotor"/>
  </actuator>
</mujoco>